Workbook

Sheet Workflows tracker
B1: ORDER | C1: ITEM | D1: JOB NAME | E1: EE | F1: MD | G1: SPECIAL PAINT | H1: RE | I1: CPD | J1: WF TYPE | K1: MECH WORKFLOW | L1: WF START DATE | M1: WF COMPLETION DATE | N1: MD WF STATUS | O1: WORKDAYS ACTIVE | P1: WORKDAYS ELAPSED (RE) | Q1: MECH NOTES/ PENDINGS | R1: EE WF TYPE | S1: ELECTRICAL WORKFLOW | T1: WF START DATE | U1: WF COMPLETION DATE | V1: EE WF STATUS | W1: ACTIVE DAYS | X1: ELECTRICAL NOTES/ PENDINGS
B2: 0051035283 | C2: 10 | D2: SWITCHGEAR UPGRADE | E2: LGS | F2: OAL | G2: STD | H2: 45709 | Q2: Finalizado | R2: MAKE | S2: WF1648774 | V2: C
Q3: Finalizado | R3: MAKE | S3: WF1645448 | V3: C
Q4: Finalizado | R4: MAKE | S4: WF1647369 | V4: C
C5: 50 | Q5: Finalizado | R5: MAKE | S5: WF1652523 | V5: C
B6: 0050206201 | C6: 000180 | D6: AT&T GREENWOOD - GEAR ORDER | E6: MGL | F6: KGF | G6: STD | H6: 45762 | J6: MAKE | K6: WF1669049 | L6: 45748 | M6: 45759 | N6: C | O6: =_xlfn.DAYS(M6,L6) -> 11 | P6: =_xlfn.DAYS(M6,H6) -> -3 | Q6: Finalizado | R6: MAKE | S6: WF1650858 | V6: C
J7: BUY | K7: WF1668571 | L7: 45747 | M7: 45758 | N7: C | O7: =_xlfn.DAYS(M7,L7) -> 11 | P7: =_xlfn.DAYS(M7,H6) -> -4 | R7: MAKE | S7: WF1650861 | V7: C | Z7: (Mech) Proceso de orden:
J8: MAKE | K8: WF1668543 | L8: 45747 | M8: 45759 | N8: C | O8: =_xlfn.DAYS(M8,L8) -> 12 | P8: =_xlfn.DAYS(M8,H6) -> -3 | R8: MAKE | S8: WF1650856 | V8: x
J9: MAKE | K9: WF1668522 | L9: 45747 | M9: 45759 | N9: C | O9: =_xlfn.DAYS(M9,L9) -> 12 | P9: =_xlfn.DAYS(M9,H6) -> -3 | R9: MAKE | S9: WF1650863 | V9: C | Z9: Finalizado | AA9: Tarea cerrada en Symmetry, orden finalizada
J10: MAKE | K10: WF1669148 | L10: 45748 | M10: 45761 | N10: C | O10: =_xlfn.DAYS(M10,L10) -> 13 | P10: =_xlfn.DAYS(M10,H6) -> -1 | R10: BUY | S10: WF1651638 | V10: C | Z10: Actualizado | AA10: BOM actualizado, pendiente cerrar tarea
J11: MAKE | K11: WF1669064 | L11: 45748 | M11: 45751 | N11: C | O11: =_xlfn.DAYS(M11,L11) -> 3 | P11: =_xlfn.DAYS(M11,H6) -> -11 | R11: MAKE | S11: WF1655340 | V11: C | Z11: Completado | AA11: Pendiente BOM y cerrar tarea, WFs completados
J12: MAKE | K12: WF1669179 | L12: 45748 | M12: 45754 | N12: C | O12: =_xlfn.DAYS(M12,L12) -> 6 | P12: =_xlfn.DAYS(M12,H6) -> -8 | R12: MAKE | S12: WF1655339 | V12: C | Z12: Cancelado | AA12: Orden cancelada
J13: MAKE | K13: WF1669735 | L13: 45749 | M13: 45756 | N13: C | O13: =_xlfn.DAYS(M13,L13) -> 7 | P13: =_xlfn.DAYS(M13,H6) -> -6 | R13: MAKE | S13: WF1657391 | V13: C
J14: BUY | K14: WF1670537 | L14: 45750 | M14: 45761 | N14: C | O14: =_xlfn.DAYS(M14,L14) -> 11 | P14: =_xlfn.DAYS(M14,H6) -> -1 | R14: MAKE | S14: WF1658163 | V14: C | Z14: Proceso de workflows:
O15: =_xlfn.DAYS(M15,L15) -> 0 | R15: MAKE | S15: WF1651072 | V15: C
B16: 0050206201 | C16: 000170 | D16: AT&T GREENWOOD - GEAR ORDER | E16: DR | F16: OAL | G16: STD | H16: 45762 | J16: MAKE | K16: WF1667259 | L16: 45743 | M16: 45759 | N16: C | O16: =_xlfn.DAYS(M16,L16) -> 16 | P16: =_xlfn.DAYS(M16,H16) -> -3 | Q16: Finalizado | R16: BUY | S16: WF1662321 | V16: x | Z16: C | AA16: Workflow completado
J17: MAKE | K17: WF1674297 | L17: 45757 | M17: 45777 | N17: C | O17: =_xlfn.DAYS(M17,L17) -> 20 | P17: =_xlfn.DAYS(M17,H16) -> 15 | R17: BUY | S17: WF1650836 | V17: C | Z17: x | AA17: Workflow cancelado
R18: MAKE | S18: WF1650838 | V18: C | Z18: xx/xx/xxxx | AA18: Fecha de último workflow completado
B19: 0050206201 | C19: 000160 | D19: AT&T GREENWOOD - GEAR ORDER | E19: JAM | F19: ADL | G19: STD | H19: 45769 | J19: MAKE | K19: WF1674295 | L19: 45757 | M19: 45770 | N19: C | O19: =_xlfn.DAYS(M19,L19) -> 13 | P19: =_xlfn.DAYS(M19,H19) -> 1 | Q19: Finalizado | R19: MAKE | S19: WF1656091 | V19: C | Z19: xx | AA19: Mayor # días activos
J20: MAKE | K20: WF1674300 | L20: 45757 | M20: 45770 | N20: C | O20: =_xlfn.DAYS(M20,L20) -> 13 | P20: =_xlfn.DAYS(M20,H19) -> 1 | R20: MAKE | S20: WF1660918 | V20: C | Z20: xx | AA20: Día más tardío desde RM
J21: MAKE | K21: WF1674297 | L21: 45757 | M21: 45777 | N21: C | O21: =_xlfn.DAYS(M21,L21) -> 20 | P21: =_xlfn.DAYS(M21,H19) -> 8 | R21: BUY | S21: WF1658800 | V21: x | Z21: I | AA21: En proceso
J22: BUY | K22: WF1670537 | L22: 45750 | M22: 45761 | N22: C | O22: =_xlfn.DAYS(M22,L22) -> 11 | P22: =_xlfn.DAYS(M22,H19) -> -8 | R22: BUY | S22: WF1671148
J23: BUY | K23: WF1668571 | L23: 45747 | M23: 45758 | N23: C | O23: =_xlfn.DAYS(M23,L23) -> 11 | P23: =_xlfn.DAYS(M23,H19) -> -11
J24: MAKE | K24: WF1676370 | L24: 45762 | M24: 45776 | N24: C | O24: =_xlfn.DAYS(M24,L24) -> 14 | P24: =_xlfn.DAYS(M24,H19) -> 7
J25: BUY | K25: WF1675631 | L25: 45761 | M25: 45777 | N25: C | O25: =_xlfn.DAYS(M25,L25) -> 16 | P25: =_xlfn.DAYS(M25,H19) -> 8
J26: MAKE | K26: WF1669148 | L26: 45748 | M26: 45761 | N26: C | O26: =_xlfn.DAYS(L26,M26) -> -13 | P26: =_xlfn.DAYS(M26,H19) -> -8 | R26: MAKE | S26: WF1648985 | V26: C
B27: 0050535728 | C27: 000130 | D27: AO SMITH MCBEE SC | E27: AOB | H27: 45702 | R27: MAKE | S27: WF1593968 | V27: C
B28: 0050465708 | C28: 000270 | D28: COLLIER COUNTY NCWRF | E28: DEV | R28: BUY | S28: WF1672649
R29: BUY | S29: WF1672650
B30: 0050546671 | C30: 460 | D30: JOHN JAY COLLEGE OF CRIMINAL JUSTI | E30: OAC | F30: VL | G30: STD | H30: 17/02/2025 | R30: BUY
R31: MAKE
R32: MAKE
E33: DMA | F33: ADL | H33: 17/02/2025 | R33: BUY
R34: MAKE
B35: 0050754152 | C35: 90 | D35: TOWER SEMICONDUCTOR - SAN ANTONIO - ALTE | E35: JTV | H35: 45705 | Q35: ON HOLD | R35: BUY | S35: WF1635286 | V35: C
R36: MAKE | S36: WF1634581 | V36: C
R37: MAKE | S37: WF1634544 | V37: C
R38: BUY | S38: WF1634504 | V38: C
R39: MAKE | S39: WF1634071 | V39: C
R40: MAKE | S40: WF1634066 | V40: C
...

Sheet Cierre de WFs
C4: JOB NAME | D4: TYPE | E4: WF | F4: START DATE | G4: DAYS ELAPSED | H4: NOTES | I4: RM
G48: =IF(ISBLANK(F48), "", NETWORKDAYS(F48, TODAY(), Holidays!$D$4:$D$19))
G49: =IF(ISBLANK(F49), "", NETWORKDAYS(F49, TODAY(), Holidays!$D$4:$D$19))
G61: =IF(ISBLANK(F61), "", NETWORKDAYS(F61, TODAY(), Holidays!$D$4:$D$19))
O256: =IF(ISBLANK(L256), "", IF(ISNUMBER(M256), NETWORKDAYS(L256, M256, 'Cierre de WFs'!J13), NETWORKDAYS(L256, TODAY(), Holidays!$D$4:$D$19)))

Sheet Holidays
D3: Holidays 2025 | E3: Holidays 2026
D4: 45658
D5: 45691
D6: 45733
D7: 45764
D8: 45765
D9: 45778
D10: 45786
D11: 45916
D12: 45961
D13: 45978
D14: 45980
D15: 45981
... D19: 46022
A23: WF INFORMATION
B28: MAKE | F28: BUY | J28: CHNG BOM
B29: Tasks | C29: Phase | D29: Total | F29: Tasks | G29: Phase | H29: Total | J29: Tasks | K29: Phase | L29: Total
B30: 7 | C30: 1 | D30: 8 | F30: 3 | G30: 1 | H30: 3 | J30: 7 | K30: 1 | L30: 7
B31: 3 | C31: 2 | D31: 10 | F31: 1 | G31: 2 | H31: 4 | J31: 1 | K31: 2 | L31: 8
B32: 4 | C32: 3 | D32: 14 | F32: 4 | G32: 3 | H32: 8 | J32: 3 | K32: 3 | L32: 11
B33: 2 | C33: 4 | D33: 16 | F33: 3 | G33: 4 | H33: 11
B34: 2 | C34: 5 | D34: 18 | F34: 3 | G34: 5 | H34: 14
B35: 2 | C35: 6 | D35: 20 | F35: 3 | G35: 6 | H35: 17
B37: TASK RESPONSIBLES
B38: Name | C38: Department
B39: JUAN CARLOS MIRANDA
B40: CARLOS CAVASOS
B41: DANIELA PAOLA GONZALEZ
B42: GRECIA JUAREZ
B43: ALEJANDRO OSUNA BALDERAS
B44: JUAN ANTONIO CABELLO
B45: ALBERTO MARTINEZ
B46: VICTOR HUGO RODRIGEZ TORRALBA
B47: ALONDRA AGUILERA
B48: REGINA LOPEZ
B49: JOSE PABLO AGUILAR
B50: ABIGAIL ESTRELLO ORTIZ
... B54: AILIA TERESA CHUCUAN

Sheet Mech Statistics
E3: AVG WORKDAYS PER WF MAKE | F3: AVG WORKDAYS PER WF BUY | G3: AVG WORKDAYS PER WF
E4: =AVERAGEIFS('Workflows tracker'!O:O, 'Workflows tracker'!J:J, "Make", 'Workflows tracker'!N:N, "C*") -> 10.711816 | F4: =AVERAGEIFS('Workflows tracker'!O:O, 'Workflows tracker'!J:J, "Buy", 'Workflows tracker'!N:N, "C*") -> 10.7 | G4: =AVERAGEIF('Workflows tracker'!N:N, "C*", 'Workflows tracker'!O:O) -> 10.681395
E10: ACTIVE WFS | F10: ACTIVE WFs > 10 WORKDAYS ELAPSED | G10: LATE ACTIVE WFs (regarding RE) | H10: TO-BE-LATE WFs (<5 workdays pre RE)
E11: =COUNTIFS('Workflows tracker'!L:L, ">0", 'Workflows tracker'!N:N, "") -> 19 | F11: =COUNTIFS('Workflows tracker'!L:L, "<>"&"", 'Workflows tracker'!N:N, "", 'Workflows tracker'!O:O, ">10") -> 13 | G11: =COUNTIFS('Workflows tracker'!L:L, "<>"&"", 'Workflows tracker'!N:N, "", 'Workflows tracker'!P:P, ">0") -> 10 | H11: =COUNTIFS('Workflows tracker'!L:L, "<>"&"", 'Workflows tracker'!N:N, "", 'Workflows tracker'!P:P, ">-5") -> 15

Sheet Filters
O1: Job name | P1: (All)
A2: Job name | B2: (All) | O2: Type | P2: (All)
A3: Type | B3: (All) | O3: Status | P3: (All)
A4: Status | B4: (All) | O4: Class | P4: (All)
A5: Class | B5: (All) | O5: Product | P5: (All)
A6: Product | B6: (All) | O6: Start Date [Month and Year] | P6: (Multiple Items)
A8: Average of Overdue Time [Expected-Completion] | B8: Average of Active Time | C8: Average of Pre RM Opening Time | D8: Count of WF | O8: Average of Overdue Time [Expected-Completion] | P8: Average of Active Time | Q8: Average of Pre RM Opening Time | R8: Count of WF
A9: 2.2429907 | B9: 9.6623832 | C9: 13.189252 | D9: 856 | O9: 1.3933333 | P9: 8.76 | Q9: 11.253333 | R9: 150
A12: Job Name | B12: (All) | O12: Job Name | P12: (All)
A13: Type | B13: (All) | O13: Type | P13: (All) | U13: Product | V13: (All)
A14: Status | B14: (All) | G14: Product | H14: (All) | O14: Status | P14: (All) | U14: Status | V14: (All)
A15: Class | B15: (All) | G15: Status | H15: (All) | O15: Class | P15: (All) | U15: Classification [Completion-Due Date] | V15: (Multiple Items)
A16: Start Date [Month and Year] | B16: (All) | G16: Classification [Completion-Due Date] | H16: (Multiple Items) | O16: Start Date [Month and Year] | P16: Mar-2026 | U16: Start Date [Month and Year] | V16: Mar-2026
A18: Classification [Completion-Due Date] | B18: Count of Classification [Completion-Due Date] | G18: Average of Overdue Time [Expected-Completion] | O18: Classification [Completion-Due Date] | P18: Count of Classification [Completion-Due Date] | U18: Average of Overdue Time [Expected-Completion]
A19: LATE | B19: 0.52219626 | G19: 5.882227 | O19: LATE | P19: 0.22413793 | U19: 5.5384615
A20: ON TIME | B20: 0.45443925 | O20: ON TIME | P20: 0.77586207 | U20: Status | V20: X
A21: SUPER LATE | B21: 0.023364486 | G21: Status | H21: X | O21: Grand Total | P21: 1 | U21: Start Date [Month and Year] | V21: Mar-2026
A22: Grand Total | B22: 1
G23: Count of WF | H23: Average of Pre RM Opening Time | I23: Average of Active Time | J23: Average of Overdue Time [Expected-Completion] | K23: Average of Impact Time Post RM | L23: Average of % Of completion | U23: Count of WF | V23: Average of Pre RM Opening Time | W23: Average of Active Time | X23: Average of Overdue Time [Expected-Completion] | Y23: Average of Impact Time Post RM | Z23: Average of % Of completion
G24: 44 | H24: 11.409091 | I24: 10.568182 | J24: 1.9545455 | K24: -1.2727273 | L24: #N/A | U24: 2 | V24: 24 | W24: 3.5 | X24: -5 | Y24: -21.5 | Z24: 0.16666667
U25: Status | V25: C
G26: Status | H26: C | U26: Start Date [Month and Year] | V26: Mar-2026
O27: Type | P27: (All)
A28: Type | B28: (All) | G28: Count of WF | H28: Average of Pre RM Opening Time | I28: Average of Active Time | J28: Average of Overdue Time [Expected-Completion] | K28: Average of Impact Time Post RM | O28: Status | P28: X | U28: Count of WF | V28: Average of Pre RM Opening Time | W28: Average of Active Time | X28: Average of Overdue Time [Expected-Completion] | Y28: Average of Impact Time Post RM
A29: Status | B29: X | G29: 764 | H29: 13.103403 | I29: 9.6034031 | J29: 2.289267 | K29: -3.2434555 | O29: Class | P29: (All) | U29: 17 | V29: 6.4117647 | W29: 4.5882353 | X29: -1.3529412 | Y29: -2.1176471
A30: Class | B30: (All) | O30: Classification [Completion-Due Date] | P30: LATE | U30: Status | V30: I
A31: Classification [Completion-Due Date] | B31: LATE | G31: Status | H31: I | O31: Start Date [Month and Year] | P31: Mar-2026 | U31: Start Date [Month and Year] | V31: Mar-2026
A33: Job Name | B33: Count of WF | C33: =COUNTA(A34:A46)-1 -> 2 | G33: Count of WF | H33: Average of Pre RM Opening Time | I33: Average of Active Time | J33: Average of Overdue Time [Expected-Completion] | K33: Average of Impact Time Post RM | O33: Job Name | P33: Count of WF | Q33: =COUNTA(O34:O36)-1 -> 0 | U33: Count of WF | V33: Average of Pre RM Opening Time | W33: Average of Active Time | X33: Average of Overdue Time [Expected-Completion] | Y33: Average of Impact Time Post RM
A34: KAISER SAN JOSE MEDICAL CENTER HOSPITAL | B34: 1 | G34: 48 | H34: 16.1875 | I34: 9.7708333 | J34: 1.7708333 | K34: -7.1041667 | O34: Grand Total | U34: 39 | V34: 15.230769 | W34: 7.9487179 | X34: -0.38461538 | Y34: -8.1025641
A35: SEA NEMA DOC1033717255 EQUIPOS ELECTRICO | B35: 1 | U35: Status | V35: (All)
A36: Grand Total | B36: 2 | G36: Status | H36: (All) | U36: Start Date [Month and Year] | V36: Mar-2026
G38: Count of WF | H38: Average of Pre RM Opening Time | I38: Average of Active Time | J38: Average of Overdue Time [Expected-Completion] | K38: Average of Impact Time Post RM | U38: Count of WF | V38: Average of Pre RM Opening Time | W38: Average of Active Time | X38: Average of Overdue Time [Expected-Completion] | Y38: Average of Impact Time Post RM
G39: 856 | H39: 13.189252 | I39: 9.6623832 | J39: 2.2429907 | K39: -3.3586449 | U39: 58 | V39: 12.948276 | W39: 6.8103448 | X39: -0.82758621 | Y39: -6.8103448
U40: Status | V40: X
G41: Status | H41: X | U41: Class | V41: Mech
G42: Class | H42: Mech | U42: Start Date [Month and Year] | V42: Mar-2026
G44: Count of WF | H44: Average of Pre RM Opening Time | I44: Average of Active Time | J44: Average of Overdue Time [Expected-Completion] | K44: Average of Impact Time Post RM | L44: Average of % Of completion | U44: Count of WF | V44: Average of Pre RM Opening Time | W44: Average of Active Time | X44: Average of Overdue Time [Expected-Completion] | Y44: Average of Impact Time Post RM | Z44: Average of % Of completion
G45: 17 | H45: 9.2941176 | I45: 11.823529 | J45: 3.7058824 | K45: 2.5882353 | L45: 0.13706267 | U45: 1 | V45: 22 | W45: 6 | X45: -3 | Y45: -17 | Z45: 0.33333333
U46: Status | V46: C
G47: Status | H47: C | U47: Class | V47: Mech
...

Sheet GSC
A1: GLOBAL STATS CALCULATIONS [PZ4/QED2/QED6]
A4: AVG Active Time | B4: AVG Overdue Time post template | C4: AVG Opening Time Pre RM | D4: %OnTime WF | E4: %Late WF | F4: %+15DAYS LATE | G4: %WF Closure by Eng Errors | H4: # Overdue Projects impacted by correct WF submittal | I4: #Projects Impacted by incorrect WF | J4: #Projects impacted by cancelation on time | K4: Top Cancellation offender | L4: Active WF
A5: =Filters!B9 -> 9.6623832 | B5: =Filters!G19 -> 5.882227 | C5: =Filters!C9 -> 13.189252 | D5: =Filters!B20 -> 0.45443925 | E5: =Filters!B19 -> 0.52219626 | F5: =Filters!B21 -> 0.023364486 | G5: =Filters!G24/Filters!D9 -> 0.051401869 | H5: =Filters!C90 -> 103 | I5: =Filters!C204 -> 28 | J5: =Filters!C55 -> 26 | K5: ACTIVE US23 | L5: =COUNTIF(WFTracker[Status],"i") -> 45
A10: AVG Active Time | B10: AVG Overdue Time post template | C10: AVG Opening Time Pre RM | D10: %OnTime WF | E10: %Late WF | F10: %+15DAYS LATE | G10: %WF Closure by Eng Errors | H10: # Overdue Projects impacted by correct WF submittal | I10: #Projects Impacted by incorrect WF | J10: #Projects impacted by cancelation on time | K10: RM Date impacted by late WFs (NOT ENG) | L10: Top Cancellation offender | M10: Active WF
A11: =Filters!P9 -> 8.76 | B11: =Filters!U19 -> 5.5384615 | C11: =Filters!Q9 -> 11.253333 | D11: =Filters!P20 -> 0.77586207 | E11: =Filters!P19 -> 0.22413793 | F11: =Filters!B27 -> 0 | G11: =Filters!U24/Filters!R9 -> 0.013333333 | H11: =Filters!Q90 -> 7 | I11: =Filters!Q200 -> 2 | J11: =Filters!Q55 -> 2 | K11: =Filters!Q268 -> 0 | L11: ACTIVE US23 | M11: =COUNTIF(WFTracker[Status],"i") -> 45

Sheet Database PZ4 + SWBD
A1: Product | B1: Order Number | C1: Item | D1: Sales Number | E1: Job Name | F1: RM | G1: RE | H1: AE | I1: MD | J1: WF | K1: Class | L1: Type | M1: Special Paint | N1: CPD | O1: Pre RM Opening Time | P1: Start date | Q1: Due date | R1: Completion Date | S1: Competion Date Content | T1: Start Date [Month and Year] | U1: Old vs New Order Lead Time WF dead line | V1: Completion Days Template | W1: Active Time | X1: Overdue Time [Expected-Completion] | Y1: Classification not considering 15+ days | Z1: Classification [Completion-Due Date] | AA1: WF SUBMITTAL [RM<5/10 DAYS] | AB1: Reason For Late WF Submital by Eng | AC1: Status | AD1: Impact Time Post RM | AE1: Impacted Post RM | AF1: Re-Worked WF Active Time | AG1: Cancelation Cause | AH1: Urgent Closure | AI1: Classification [Completion-RM] | AJ1: Task responsible | AK1: Task Number | AL1: Completion Forecast | AM1: % Of completion | AN1: Comments
A2: =IF(WFTracker[[#This Row],[Order Number]]="SWBD", "QED2", "PZ4") -> PZ4 | B2: 0050535728 | C2: 000130 | D2: =WFTracker[[#This Row],[Order Number]] & "-" & WFTracker[[#This Row],[Item]] -> 0050535728-000130 | E2: AO SMITH MCBEE SC | F2: 45702 | H2: AOB | I2: OAL | J2: WF1593968 | K2: Elec | L2: MAKE | M2: ANSI 49 | N2: 45824 | O2: =NETWORKDAYS.INTL(WFTracker[[#This Row],[Start date]],WFTracker[[#This Row],[RM]],1,Holidays!D619:D634) -> 90 | P2: 45579 | Q2: 45586 | R2: 45600 | S2: =ISBLANK(WFTracker[[#This Row],[Completion Date]]) -> FALSE | T2: =TEXT(WFTracker[[#This Row],[Start date]],"mmm-yyyy") -> Oct-2024 | U2: 5 | V2: =NETWORKDAYS.INTL(WFTracker[[#This Row],[Start date]],WFTracker[[#This Row],[Due date]],1,Holidays!D619:D634) -> 6 | W2: =IF(WFTracker[[#This Row],[Competion Date Content]]= TRUE, NETWORKDAYS.INTL( WFTracker[[#This Row],[Start date]],TODAY(),1,Holidays!$D$4:$D$19), NETWORKDAYS.INTL( WFTracker[[#This Row],[Start date]],WFTracker[[#This Row],[Completion Date]],1,Holidays!$D$4:$D$19)) -> 16 | X2: =WFTracker[[#This Row],[Active Time]]-WFTracker[[#This Row],[Completion Days Template]] -> 10 | Y2: =IF(WFTracker[[#This Row],[Overdue Time '[Expected-Completion']]]>0, "LATE","ON TIME") -> LATE | Z2: =IF(WFTracker[[#This Row],[Overdue Time '[Expected-Completion']]] >= 15, "SUPER LATE", Y2) -> LATE | AA2: =IF(WFTracker[[#This Row],[Pre RM Opening Time]]<WFTracker[[#This Row],[Old vs New Order Lead Time WF dead line]], "LATE BY ENG", "ON TIME BY ENG") -> ON TIME BY ENG | AC2: C | AD2: =IF(WFTracker[[#This Row],[Competion Date Content]]=TRUE,NETWORKDAYS.INTL(WFTracker[[#This Row],[RM]],TODAY(),1,Holidays!$D$4:$D$19), NETWORKDAYS.INTL(WFTracker[[#This Row],[RM]],WFTracker[[#This Row],[Completion Date]],1,Holidays!$D$4:$D$19)) -> -73 | AE2: =IF(WFTracker[[#This Row],[Impact Time Post RM]]>0, "IMPACTED", "NOT IMPACTED") -> NOT IMPACTED | AH2: =IF(WFTracker[[#This Row],[Status]]="C", "Closed", IF(WFTracker[[#This Row],[Status]] = "x", "Cancelled", WFTracker[[#This Row],[Impact Time Post RM]])) -> Closed | AI2: =IF(WFTracker[[#This Row],[Impact Time Post RM]]<=0,"ON TIME","LATE") -> ON TIME | AJ2: NA | AK2: 18 | AL2: =IF(WFTracker[[#This Row],[Type]]="MAKE", WFTracker[[#This Row],[Due date]]+Filters!$J$111, WFTracker[[#This Row],[Due date]]+Filters!$J$135) -> 45589.073 | AM2: {=_xlfn.IFS(WFTracker[[#This Row],[Type]]="BUY", WFTracker[[#This Row],[Task Number]]/17, WFTracker[[#This Row],[Type]]="MAKE", WFTracker[[#This Row],[Task Number]]/18, WFTracker[[#This Row],[Type]]="CNG-BOM", WFTracker[[#This Row],[Task Number]]/11)} -> 1
A3: =IF(WFTracker[[#This Row],[Order Number]]="SWBD", "QED2", "PZ4") -> PZ4 | B3: 0050754152 | C3: 000090 | D3: =WFTracker[[#This Row],[Order Number]] & "-" & WFTracker[[#This Row],[Item]] -> 0050754152-000090 | E3: TOWER SEMICONDUCTOR - SAN ANTONIO - ALTE | F3: 45705 | H3: JTV | I3: LDT | J3: WF1634065 | K3: Mech | L3: MAKE | M3: ANSI 49 | N3: 45922 | O3: =NETWORKDAYS.INTL(WFTracker[[#This Row],[Start date]],WFTracker[[#This Row],[RM]],1,Holidays!D465:D480) -> 21 | P3: 45677 | Q3: 45686 | R3: 45693 | S3: =ISBLANK(WFTracker[[#This Row],[Completion Date]]) -> FALSE | T3: =TEXT(WFTracker[[#This Row],[Start date]],"mmm-yyyy") -> Jan-2025 | U3: 5 | V3: =NETWORKDAYS.INTL(WFTracker[[#This Row],[Start date]],WFTracker[[#This Row],[Due date]],1,Holidays!D465:D480) -> 8 | W3: =IF(WFTracker[[#This Row],[Competion Date Content]]= TRUE, NETWORKDAYS.INTL( WFTracker[[#This Row],[Start date]],TODAY(),1,Holidays!$D$4:$D$19), NETWORKDAYS.INTL( WFTracker[[#This Row],[Start date]],WFTracker[[#This Row],[Completion Date]],1,Holidays!$D$4:$D$19)) -> 12 | X3: =WFTracker[[#This Row],[Active Time]]-WFTracker[[#This Row],[Completion Days Template]] -> 4 | Y3: =IF(WFTracker[[#This Row],[Overdue Time '[Expected-Completion']]]>0, "LATE","ON TIME") -> LATE | Z3: =IF(WFTracker[[#This Row],[Overdue Time '[Expected-Completion']]] >= 15, "SUPER LATE", Y3) -> LATE | AA3: =IF(WFTracker[[#This Row],[Pre RM Opening Time]]<WFTracker[[#This Row],[Old vs New Order Lead Time WF dead line]], "LATE BY ENG", "ON TIME BY ENG") -> ON TIME BY ENG | AC3: C | AD3: =IF(WFTracker[[#This Row],[Competion Date Content]]=TRUE,NETWORKDAYS.INTL(WFTracker[[#This Row],[RM]],TODAY(),1,Holidays!$D$4:$D$19), NETWORKDAYS.INTL(WFTracker[[#This Row],[RM]],WFTracker[[#This Row],[Completion Date]],1,Holidays!$D$4:$D$19)) -> -9 | AE3: =IF(WFTracker[[#This Row],[Impact Time Post RM]]>0, "IMPACTED", "NOT IMPACTED") -> NOT IMPACTED | AH3: =IF(WFTracker[[#This Row],[Status]]="C", "Closed", IF(WFTracker[[#This Row],[Status]] = "x", "Cancelled", WFTracker[[#This Row],[Impact Time Post RM]])) -> Closed | AI3: =IF(WFTracker[[#This Row],[Impact Time Post RM]]<=0,"ON TIME","LATE") -> ON TIME | AJ3: NA | AK3: 18 | AL3: =IF(WFTracker[[#This Row],[Type]]="MAKE", WFTracker[[#This Row],[Due date]]+Filters!$J$111, WFTracker[[#This Row],[Due date]]+Filters!$J$135) -> 45689.073 | AM3: {=_xlfn.IFS(WFTracker[[#This Row],[Type]]="BUY", WFTracker[[#This Row],[Task Number]]/17, WFTracker[[#This Row],[Type]]="MAKE", WFTracker[[#This Row],[Task Number]]/18, WFTracker[[#This Row],[Type]]="CNG-BOM", WFTracker[[#This Row],[Task Number]]/11)} -> 1
A4: =IF(WFTracker[[#This Row],[Order Number]]="SWBD", "QED2", "PZ4") -> PZ4 | B4: 0050754152 | C4: 000090 | D4: =WFTracker[[#This Row],[Order Number]] & "-" & WFTracker[[#This Row],[Item]] -> 0050754152-000090 | E4: TOWER SEMICONDUCTOR - SAN ANTONIO - ALTE | F4: 45705 | H4: JTV | I4: LDT | J4: WF1634066 | K4: Mech | L4: MAKE | M4: ANSI 49 | N4: 45922 | O4: =NETWORKDAYS.INTL(WFTracker[[#This Row],[Start date]],WFTracker[[#This Row],[RM]],1,Holidays!D466:D481) -> 21 | P4: 45677 | Q4: 45686 | R4: 45693 | S4: =ISBLANK(WFTracker[[#This Row],[Completion Date]]) -> FALSE | T4: =TEXT(WFTracker[[#This Row],[Start date]],"mmm-yyyy") -> Jan-2025 | U4: 5 | V4: =NETWORKDAYS.INTL(WFTracker[[#This Row],[Start date]],WFTracker[[#This Row],[Due date]],1,Holidays!D466:D481) -> 8 | W4: =IF(WFTracker[[#This Row],[Competion Date Content]]= TRUE, NETWORKDAYS.INTL( WFTracker[[#This Row],[Start date]],TODAY(),1,Holidays!$D$4:$D$19), NETWORKDAYS.INTL( WFTracker[[#This Row],[Start date]],WFTracker[[#This Row],[Completion Date]],1,Holidays!$D$4:$D$19)) -> 12 | X4: =WFTracker[[#This Row],[Active Time]]-WFTracker[[#This Row],[Completion Days Template]] -> 4 | Y4: =IF(WFTracker[[#This Row],[Overdue Time '[Expected-Completion']]]>0, "LATE","ON TIME") -> LATE | Z4: =IF(WFTracker[[#This Row],[Overdue Time '[Expected-Completion']]] >= 15, "SUPER LATE", Y4) -> LATE | AA4: =IF(WFTracker[[#This Row],[Pre RM Opening Time]]<WFTracker[[#This Row],[Old vs New Order Lead Time WF dead line]], "LATE BY ENG", "ON TIME BY ENG") -> ON TIME BY ENG | AC4: C | AD4: =IF(WFTracker[[#This Row],[Competion Date Content]]=TRUE,NETWORKDAYS.INTL(WFTracker[[#This Row],[RM]],TODAY(),1,Holidays!$D$4:$D$19), NETWORKDAYS.INTL(WFTracker[[#This Row],[RM]],WFTracker[[#This Row],[Completion Date]],1,Holidays!$D$4:$D$19)) -> -9 | AE4: =IF(WFTracker[[#This Row],[Impact Time Post RM]]>0, "IMPACTED", "NOT IMPACTED") -> NOT IMPACTED | AH4: =IF(WFTracker[[#This Row],[Status]]="C", "Closed", IF(WFTracker[[#This Row],[Status]] = "x", "Cancelled", WFTracker[[#This Row],[Impact Time Post RM]])) -> Closed | AI4: =IF(WFTracker[[#This Row],[Impact Time Post RM]]<=0,"ON TIME","LATE") -> ON TIME | AJ4: NA | AK4: 18 | AL4: =IF(WFTracker[[#This Row],[Type]]="MAKE", WFTracker[[#This Row],[Due date]]+Filters!$J$111, WFTracker[[#This Row],[Due date]]+Filters!$J$135) -> 45689.073 | AM4: {=_xlfn.IFS(WFTracker[[#This Row],[Type]]="BUY", WFTracker[[#This Row],[Task Number]]/17, WFTracker[[#This Row],[Type]]="MAKE", WFTracker[[#This Row],[Task Number]]/18, WFTracker[[#This Row],[Type]]="CNG-BOM", WFTracker[[#This Row],[Task Number]]/11)} -> 1
A5: =IF(WFTracker[[#This Row],[Order Number]]="SWBD", "QED2", "PZ4") -> PZ4 | B5: 0050754152 | C5: 000090 | D5: =WFTracker[[#This Row],[Order Number]] & "-" & WFTracker[[#This Row],[Item]] -> 0050754152-000090 | E5: TOWER SEMICONDUCTOR - SAN ANTONIO - ALTE | F5: 45705 | H5: JTV | I5: LDT | J5: WF1634071 | K5: Mech | L5: MAKE | M5: ANSI 49 | N5: 45922 | O5: =NETWORKDAYS.INTL(WFTracker[[#This Row],[Start date]],WFTracker[[#This Row],[RM]],1,Holidays!D467:D482) -> 21 | P5: 45677 | Q5: 45686 | R5: 45693 | S5: =ISBLANK(WFTracker[[#This Row],[Completion Date]]) -> FALSE | T5: =TEXT(WFTracker[[#This Row],[Start date]],"mmm-yyyy") -> Jan-2025 | U5: 5 | V5: =NETWORKDAYS.INTL(WFTracker[[#This Row],[Start date]],WFTracker[[#This Row],[Due date]],1,Holidays!D467:D482) -> 8 | W5: =IF(WFTracker[[#This Row],[Competion Date Content]]= TRUE, NETWORKDAYS.INTL( WFTracker[[#This Row],[Start date]],TODAY(),1,Holidays!$D$4:$D$19), NETWORKDAYS.INTL( WFTracker[[#This Row],[Start date]],WFTracker[[#This Row],[Completion Date]],1,Holidays!$D$4:$D$19)) -> 12 | X5: =WFTracker[[#This Row],[Active Time]]-WFTracker[[#This Row],[Completion Days Template]] -> 4 | Y5: =IF(WFTracker[[#This Row],[Overdue Time '[Expected-Completion']]]>0, "LATE","ON TIME") -> LATE | Z5: =IF(WFTracker[[#This Row],[Overdue Time '[Expected-Completion']]] >= 15, "SUPER LATE", Y5) -> LATE | AA5: =IF(WFTracker[[#This Row],[Pre RM Opening Time]]<WFTracker[[#This Row],[Old vs New Order Lead Time WF dead line]], "LATE BY ENG", "ON TIME BY ENG") -> ON TIME BY ENG | AC5: C | AD5: =IF(WFTracker[[#This Row],[Competion Date Content]]=TRUE,NETWORKDAYS.INTL(WFTracker[[#This Row],[RM]],TODAY(),1,Holidays!$D$4:$D$19), NETWORKDAYS.INTL(WFTracker[[#This Row],[RM]],WFTracker[[#This Row],[Completion Date]],1,Holidays!$D$4:$D$19)) -> -9 | AE5: =IF(WFTracker[[#This Row],[Impact Time Post RM]]>0, "IMPACTED", "NOT IMPACTED") -> NOT IMPACTED | AH5: =IF(WFTracker[[#This Row],[Status]]="C", "Closed", IF(WFTracker[[#This Row],[Status]] = "x", "Cancelled", WFTracker[[#This Row],[Impact Time Post RM]])) -> Closed | AI5: =IF(WFTracker[[#This Row],[Impact Time Post RM]]<=0,"ON TIME","LATE") -> ON TIME | AJ5: NA | AK5: 18 | AL5: =IF(WFTracker[[#This Row],[Type]]="MAKE", WFTracker[[#This Row],[Due date]]+Filters!$J$111, WFTracker[[#This Row],[Due date]]+Filters!$J$135) -> 45689.073 | AM5: {=_xlfn.IFS(WFTracker[[#This Row],[Type]]="BUY", WFTracker[[#This Row],[Task Number]]/17, WFTracker[[#This Row],[Type]]="MAKE", WFTracker[[#This Row],[Task Number]]/18, WFTracker[[#This Row],[Type]]="CNG-BOM", WFTracker[[#This Row],[Task Number]]/11)} -> 1
A6: =IF(WFTracker[[#This Row],[Order Number]]="SWBD", "QED2", "PZ4") -> PZ4 | B6: 0050529183 | C6: 000460 | D6: =WFTracker[[#This Row],[Order Number]] & "-" & WFTracker[[#This Row],[Item]] -> 0050529183-000460 | E6: USSF ANTENNA FACILITY PROJECT | F6: 45713 | H6: AOB | I6: DPM | J6: WF1634013 | K6: Elec | L6: BUY | M6: MISAWA | N6: 45915 | O6: =NETWORKDAYS.INTL(WFTracker[[#This Row],[Start date]],WFTracker[[#This Row],[RM]],1,Holidays!D518:D533) -> 27 | P6: 45677 | Q6: 45687 | R6: 45727 | S6: =ISBLANK(WFTracker[[#This Row],[Completion Date]]) -> FALSE | T6: =TEXT(WFTracker[[#This Row],[Start date]],"mmm-yyyy") -> Jan-2025 | U6: 5 | V6: =NETWORKDAYS.INTL(WFTracker[[#This Row],[Start date]],WFTracker[[#This Row],[Due date]],1,Holidays!D518:D533) -> 9 | W6: =IF(WFTracker[[#This Row],[Competion Date Content]]= TRUE, NETWORKDAYS.INTL( WFTracker[[#This Row],[Start date]],TODAY(),1,Holidays!$D$4:$D$19), NETWORKDAYS.INTL( WFTracker[[#This Row],[Start date]],WFTracker[[#This Row],[Completion Date]],1,Holidays!$D$4:$D$19)) -> 36 | X6: =WFTracker[[#This Row],[Active Time]]-WFTracker[[#This Row],[Completion Days Template]] -> 27 | Y6: =IF(WFTracker[[#This Row],[Overdue Time '[Expected-Completion']]]>0, "LATE","ON TIME") -> LATE | Z6: =IF(WFTracker[[#This Row],[Overdue Time '[Expected-Completion']]] >= 15, "SUPER LATE", Y6) -> SUPER LATE | AA6: =IF(WFTracker[[#This Row],[Pre RM Opening Time]]<WFTracker[[#This Row],[Old vs New Order Lead Time WF dead line]], "LATE BY ENG", "ON TIME BY ENG") -> ON TIME BY ENG | AC6: C | AD6: =IF(WFTracker[[#This Row],[Competion Date Content]]=TRUE,NETWORKDAYS.INTL(WFTracker[[#This Row],[RM]],TODAY(),1,Holidays!$D$4:$D$19), NETWORKDAYS.INTL(WFTracker[[#This Row],[RM]],WFTracker[[#This Row],[Completion Date]],1,Holidays!$D$4:$D$19)) -> 11 | AE6: =IF(WFTracker[[#This Row],[Impact Time Post RM]]>0, "IMPACTED", "NOT IMPACTED") -> IMPACTED | AH6: =IF(WFTracker[[#This Row],[Status]]="C", "Closed", IF(WFTracker[[#This Row],[Status]] = "x", "Cancelled", WFTracker[[#This Row],[Impact Time Post RM]])) -> Closed | AI6: =IF(WFTracker[[#This Row],[Impact Time Post RM]]<=0,"ON TIME","LATE") -> LATE | AJ6: NA | AK6: 17 | AL6: =IF(WFTracker[[#This Row],[Type]]="MAKE", WFTracker[[#This Row],[Due date]]+Filters!$J$111, WFTracker[[#This Row],[Due date]]+Filters!$J$135) -> 45687.416 | AM6: {=_xlfn.IFS(WFTracker[[#This Row],[Type]]="BUY", WFTracker[[#This Row],[Task Number]]/17, WFTracker[[#This Row],[Type]]="MAKE", WFTracker[[#This Row],[Task Number]]/18, WFTracker[[#This Row],[Type]]="CNG-BOM", WFTracker[[#This Row],[Task Number]]/11)} -> 1
A7: =IF(WFTracker[[#This Row],[Order Number]]="SWBD", "QED2", "PZ4") -> PZ4 | B7: 0050754152 | C7: 000090 | D7: =WFTracker[[#This Row],[Order Number]] & "-" & WFTracker[[#This Row],[Item]] -> 0050754152-000090 | E7: TOWER SEMICONDUCTOR - SAN ANTONIO - ALTE | F7: 45705 | H7: JTV | I7: LDT | J7: WF1634544 | K7: Mech | L7: MAKE | M7: ANSI 49 | N7: 45922 | O7: =NETWORKDAYS.INTL(WFTracker[[#This Row],[Start date]],WFTracker[[#This Row],[RM]],1,Holidays!D445:D460) -> 20 | P7: 45678 | Q7: 45685 | R7: 45693 | S7: =ISBLANK(WFTracker[[#This Row],[Completion Date]]) -> FALSE | T7: =TEXT(WFTracker[[#This Row],[Start date]],"mmm-yyyy") -> Jan-2025 | U7: 5 | V7: =NETWORKDAYS.INTL(WFTracker[[#This Row],[Start date]],WFTracker[[#This Row],[Due date]],1,Holidays!D445:D460) -> 6 | W7: =IF(WFTracker[[#This Row],[Competion Date Content]]= TRUE, NETWORKDAYS.INTL( WFTracker[[#This Row],[Start date]],TODAY(),1,Holidays!$D$4:$D$19), NETWORKDAYS.INTL( WFTracker[[#This Row],[Start date]],WFTracker[[#This Row],[Completion Date]],1,Holidays!$D$4:$D$19)) -> 11 | X7: =WFTracker[[#This Row],[Active Time]]-WFTracker[[#This Row],[Completion Days Template]] -> 5 | Y7: =IF(WFTracker[[#This Row],[Overdue Time '[Expected-Completion']]]>0, "LATE","ON TIME") -> LATE | Z7: =IF(WFTracker[[#This Row],[Overdue Time '[Expected-Completion']]] >= 15, "SUPER LATE", Y7) -> LATE | AA7: =IF(WFTracker[[#This Row],[Pre RM Opening Time]]<WFTracker[[#This Row],[Old vs New Order Lead Time WF dead line]], "LATE BY ENG", "ON TIME BY ENG") -> ON TIME BY ENG | AC7: C | AD7: =IF(WFTracker[[#This Row],[Competion Date Content]]=TRUE,NETWORKDAYS.INTL(WFTracker[[#This Row],[RM]],TODAY(),1,Holidays!$D$4:$D$19), NETWORKDAYS.INTL(WFTracker[[#This Row],[RM]],WFTracker[[#This Row],[Completion Date]],1,Holidays!$D$4:$D$19)) -> -9 | AE7: =IF(WFTracker[[#This Row],[Impact Time Post RM]]>0, "IMPACTED", "NOT IMPACTED") -> NOT IMPACTED | AH7: =IF(WFTracker[[#This Row],[Status]]="C", "Closed", IF(WFTracker[[#This Row],[Status]] = "x", "Cancelled", WFTracker[[#This Row],[Impact Time Post RM]])) -> Closed | AI7: =IF(WFTracker[[#This Row],[Impact Time Post RM]]<=0,"ON TIME","LATE") -> ON TIME | AJ7: NA | AK7: 18 | AL7: =IF(WFTracker[[#This Row],[Type]]="MAKE", WFTracker[[#This Row],[Due date]]+Filters!$J$111, WFTracker[[#This Row],[Due date]]+Filters!$J$135) -> 45688.073 | AM7: {=_xlfn.IFS(WFTracker[[#This Row],[Type]]="BUY", WFTracker[[#This Row],[Task Number]]/17, WFTracker[[#This Row],[Type]]="MAKE", WFTracker[[#This Row],[Task Number]]/18, WFTracker[[#This Row],[Type]]="CNG-BOM", WFTracker[[#This Row],[Task Number]]/11)} -> 1
A8: =IF(WFTracker[[#This Row],[Order Number]]="SWBD", "QED2", "PZ4") -> PZ4 | B8: 0050754152 | C8: 000090 | D8: =WFTracker[[#This Row],[Order Number]] & "-" & WFTracker[[#This Row],[Item]] -> 0050754152-000090 | E8: TOWER SEMICONDUCTOR - SAN ANTONIO - ALTE | F8: 45705 | H8: JTV | I8: LDT | J8: WF1634581 | K8: Mech | L8: MAKE | M8: ANSI 49 | N8: 45922 | O8: =NETWORKDAYS.INTL(WFTracker[[#This Row],[Start date]],WFTracker[[#This Row],[RM]],1,Holidays!D446:D461) -> 20 | P8: 45678 | Q8: 45685 | R8: 45688 | S8: =ISBLANK(WFTracker[[#This Row],[Completion Date]]) -> FALSE | T8: =TEXT(WFTracker[[#This Row],[Start date]],"mmm-yyyy") -> Jan-2025 | U8: 5 | V8: =NETWORKDAYS.INTL(WFTracker[[#This Row],[Start date]],WFTracker[[#This Row],[Due date]],1,Holidays!D446:D461) -> 6 | W8: =IF(WFTracker[[#This Row],[Competion Date Content]]= TRUE, NETWORKDAYS.INTL( WFTracker[[#This Row],[Start date]],TODAY(),1,Holidays!$D$4:$D$19), NETWORKDAYS.INTL( WFTracker[[#This Row],[Start date]],WFTracker[[#This Row],[Completion Date]],1,Holidays!$D$4:$D$19)) -> 9 | X8: =WFTracker[[#This Row],[Active Time]]-WFTracker[[#This Row],[Completion Days Template]] -> 3 | Y8: =IF(WFTracker[[#This Row],[Overdue Time '[Expected-Completion']]]>0, "LATE","ON TIME") -> LATE | Z8: =IF(WFTracker[[#This Row],[Overdue Time '[Expected-Completion']]] >= 15, "SUPER LATE", Y8) -> LATE | AA8: =IF(WFTracker[[#This Row],[Pre RM Opening Time]]<WFTracker[[#This Row],[Old vs New Order Lead Time WF dead line]], "LATE BY ENG", "ON TIME BY ENG") -> ON TIME BY ENG | AC8: C | AD8: =IF(WFTracker[[#This Row],[Competion Date Content]]=TRUE,NETWORKDAYS.INTL(WFTracker[[#This Row],[RM]],TODAY(),1,Holidays!$D$4:$D$19), NETWORKDAYS.INTL(WFTracker[[#This Row],[RM]],WFTracker[[#This Row],[Completion Date]],1,Holidays!$D$4:$D$19)) -> -11 | AE8: =IF(WFTracker[[#This Row],[Impact Time Post RM]]>0, "IMPACTED", "NOT IMPACTED") -> NOT IMPACTED | AH8: =IF(WFTracker[[#This Row],[Status]]="C", "Closed", IF(WFTracker[[#This Row],[Status]] = "x", "Cancelled", WFTracker[[#This Row],[Impact Time Post RM]])) -> Closed | AI8: =IF(WFTracker[[#This Row],[Impact Time Post RM]]<=0,"ON TIME","LATE") -> ON TIME | AJ8: NA | AK8: 18 | AL8: =IF(WFTracker[[#This Row],[Type]]="MAKE", WFTracker[[#This Row],[Due date]]+Filters!$J$111, WFTracker[[#This Row],[Due date]]+Filters!$J$135) -> 45688.073 | AM8: {=_xlfn.IFS(WFTracker[[#This Row],[Type]]="BUY", WFTracker[[#This Row],[Task Number]]/17, WFTracker[[#This Row],[Type]]="MAKE", WFTracker[[#This Row],[Task Number]]/18, WFTracker[[#This Row],[Type]]="CNG-BOM", WFTracker[[#This Row],[Task Number]]/11)} -> 1
A9: =IF(WFTracker[[#This Row],[Order Number]]="SWBD", "QED2", "PZ4") -> PZ4 | B9: 0050754152 | C9: 000090 | D9: =WFTracker[[#This Row],[Order Number]] & "-" & WFTracker[[#This Row],[Item]] -> 0050754152-000090 | E9: TOWER SEMICONDUCTOR - SAN ANTONIO - ALTE | F9: 45705 | H9: JTV | I9: LDT | J9: WF1634504 | K9: Mech | L9: BUY | M9: ANSI 49 | N9: 45922 | O9: =NETWORKDAYS.INTL(WFTracker[[#This Row],[Start date]],WFTracker[[#This Row],[RM]],1,Holidays!D447:D462) -> 20 | P9: 45678 | Q9: 45688 | R9: 45686 | S9: =ISBLANK(WFTracker[[#This Row],[Completion Date]]) -> FALSE | T9: =TEXT(WFTracker[[#This Row],[Start date]],"mmm-yyyy") -> Jan-2025 | U9: 5 | V9: =NETWORKDAYS.INTL(WFTracker[[#This Row],[Start date]],WFTracker[[#This Row],[Due date]],1,Holidays!D447:D462) -> 9 | W9: =IF(WFTracker[[#This Row],[Competion Date Content]]= TRUE, NETWORKDAYS.INTL( WFTracker[[#This Row],[Start date]],TODAY(),1,Holidays!$D$4:$D$19), NETWORKDAYS.INTL( WFTracker[[#This Row],[Start date]],WFTracker[[#This Row],[Completion Date]],1,Holidays!$D$4:$D$19)) -> 7 | X9: =WFTracker[[#This Row],[Active Time]]-WFTracker[[#This Row],[Completion Days Template]] -> -2 | Y9: =IF(WFTracker[[#This Row],[Overdue Time '[Expected-Completion']]]>0, "LATE","ON TIME") -> ON TIME | Z9: =IF(WFTracker[[#This Row],[Overdue Time '[Expected-Completion']]] >= 15, "SUPER LATE", Y9) -> ON TIME | AA9: =IF(WFTracker[[#This Row],[Pre RM Opening Time]]<WFTracker[[#This Row],[Old vs New Order Lead Time WF dead line]], "LATE BY ENG", "ON TIME BY ENG") -> ON TIME BY ENG | AC9: C | AD9: =IF(WFTracker[[#This Row],[Competion Date Content]]=TRUE,NETWORKDAYS.INTL(WFTracker[[#This Row],[RM]],TODAY(),1,Holidays!$D$4:$D$19), NETWORKDAYS.INTL(WFTracker[[#This Row],[RM]],WFTracker[[#This Row],[Completion Date]],1,Holidays!$D$4:$D$19)) -> -13 | AE9: =IF(WFTracker[[#This Row],[Impact Time Post RM]]>0, "IMPACTED", "NOT IMPACTED") -> NOT IMPACTED | AH9: =IF(WFTracker[[#This Row],[Status]]="C", "Closed", IF(WFTracker[[#This Row],[Status]] = "x", "Cancelled", WFTracker[[#This Row],[Impact Time Post RM]])) -> Closed | AI9: =IF(WFTracker[[#This Row],[Impact Time Post RM]]<=0,"ON TIME","LATE") -> ON TIME | AJ9: NA | AK9: 17 | AL9: =IF(WFTracker[[#This Row],[Type]]="MAKE", WFTracker[[#This Row],[Due date]]+Filters!$J$111, WFTracker[[#This Row],[Due date]]+Filters!$J$135) -> 45688.416 | AM9: {=_xlfn.IFS(WFTracker[[#This Row],[Type]]="BUY", WFTracker[[#This Row],[Task Number]]/17, WFTracker[[#This Row],[Type]]="MAKE", WFTracker[[#This Row],[Task Number]]/18, WFTracker[[#This Row],[Type]]="CNG-BOM", WFTracker[[#This Row],[Task Number]]/11)} -> 1
A10: =IF(WFTracker[[#This Row],[Order Number]]="SWBD", "QED2", "PZ4") -> PZ4 | B10: 0050754152 | C10: 000090 | D10: =WFTracker[[#This Row],[Order Number]] & "-" & WFTracker[[#This Row],[Item]] -> 0050754152-000090 | E10: TOWER SEMICONDUCTOR - SAN ANTONIO - ALTE | F10: 45705 | H10: JTV | I10: LDT | J10: WF1635286 | K10: Elec | L10: BUY | M10: ANSI 49 | N10: 45922 | O10: =NETWORKDAYS.INTL(WFTracker[[#This Row],[Start date]],WFTracker[[#This Row],[RM]],1,Holidays!D425:D440) -> 19 | P10: 45679 | Q10: 45691 | R10: 45693 | S10: =ISBLANK(WFTracker[[#This Row],[Completion Date]]) -> FALSE | T10: =TEXT(WFTracker[[#This Row],[Start date]],"mmm-yyyy") -> Jan-2025 | U10: 5 | V10: =NETWORKDAYS.INTL(WFTracker[[#This Row],[Start date]],WFTracker[[#This Row],[Due date]],1,Holidays!D425:D440) -> 9 | W10: =IF(WFTracker[[#This Row],[Competion Date Content]]= TRUE, NETWORKDAYS.INTL( WFTracker[[#This Row],[Start date]],TODAY(),1,Holidays!$D$4:$D$19), NETWORKDAYS.INTL( WFTracker[[#This Row],[Start date]],WFTracker[[#This Row],[Completion Date]],1,Holidays!$D$4:$D$19)) -> 10 | X10: =WFTracker[[#This Row],[Active Time]]-WFTracker[[#This Row],[Completion Days Template]] -> 1 | Y10: =IF(WFTracker[[#This Row],[Overdue Time '[Expected-Completion']]]>0, "LATE","ON TIME") -> LATE | Z10: =IF(WFTracker[[#This Row],[Overdue Time '[Expected-Completion']]] >= 15, "SUPER LATE", Y10) -> LATE | AA10: =IF(WFTracker[[#This Row],[Pre RM Opening Time]]<WFTracker[[#This Row],[Old vs New Order Lead Time WF dead line]], "LATE BY ENG", "ON TIME BY ENG") -> ON TIME BY ENG | AC10: C | AD10: =IF(WFTracker[[#This Row],[Competion Date Content]]=TRUE,NETWORKDAYS.INTL(WFTracker[[#This Row],[RM]],TODAY(),1,Holidays!$D$4:$D$19), NETWORKDAYS.INTL(WFTracker[[#This Row],[RM]],WFTracker[[#This Row],[Completion Date]],1,Holidays!$D$4:$D$19)) -> -9 | AE10: =IF(WFTracker[[#This Row],[Impact Time Post RM]]>0, "IMPACTED", "NOT IMPACTED") -> NOT IMPACTED | AH10: =IF(WFTracker[[#This Row],[Status]]="C", "Closed", IF(WFTracker[[#This Row],[Status]] = "x", "Cancelled", WFTracker[[#This Row],[Impact Time Post RM]])) -> Closed | AI10: =IF(WFTracker[[#This Row],[Impact Time Post RM]]<=0,"ON TIME","LATE") -> ON TIME | AJ10: NA | AK10: 17 | AL10: =IF(WFTracker[[#This Row],[Type]]="MAKE", WFTracker[[#This Row],[Due date]]+Filters!$J$111, WFTracker[[#This Row],[Due date]]+Filters!$J$135) -> 45691.416 | AM10: {=_xlfn.IFS(WFTracker[[#This Row],[Type]]="BUY", WFTracker[[#This Row],[Task Number]]/17, WFTracker[[#This Row],[Type]]="MAKE", WFTracker[[#This Row],[Task Number]]/18, WFTracker[[#This Row],[Type]]="CNG-BOM", WFTracker[[#This Row],[Task Number]]/11)} -> 1
A11: =IF(WFTracker[[#This Row],[Order Number]]="SWBD", "QED2", "PZ4") -> PZ4 | B11: 0051035283 | C11: 0000010&0000050 | D11: =WFTracker[[#This Row],[Order Number]] & "-" & WFTracker[[#This Row],[Item]] -> 0051035283-0000010&0000050 | E11: SWITCHGEAR UPGRADE | F11: 45709 | H11: LGS | I11: OAL | J11: WF1645448 | K11: Elec | L11: MAKE | M11: ANSI 49 | N11: 45835 | O11: =NETWORKDAYS.INTL(WFTracker[[#This Row],[Start date]],WFTracker[[#This Row],[RM]],1,Holidays!D152:D167) -> 8 | P11: 45700 | Q11: 45708 | R11: 45720 | S11: =ISBLANK(WFTracker[[#This Row],[Completion Date]]) -> FALSE | T11: =TEXT(WFTracker[[#This Row],[Start date]],"mmm-yyyy") -> Feb-2025 | U11: 5 | V11: =NETWORKDAYS.INTL(WFTracker[[#This Row],[Start date]],WFTracker[[#This Row],[Due date]],1,Holidays!D152:D167) -> 7 | W11: =IF(WFTracker[[#This Row],[Competion Date Content]]= TRUE, NETWORKDAYS.INTL( WFTracker[[#This Row],[Start date]],TODAY(),1,Holidays!$D$4:$D$19), NETWORKDAYS.INTL( WFTracker[[#This Row],[Start date]],WFTracker[[#This Row],[Completion Date]],1,Holidays!$D$4:$D$19)) -> 15 | X11: =WFTracker[[#This Row],[Active Time]]-WFTracker[[#This Row],[Completion Days Template]] -> 8 | Y11: =IF(WFTracker[[#This Row],[Overdue Time '[Expected-Completion']]]>0, "LATE","ON TIME") -> LATE | Z11: =IF(WFTracker[[#This Row],[Overdue Time '[Expected-Completion']]] >= 15, "SUPER LATE", Y11) -> LATE | AA11: =IF(WFTracker[[#This Row],[Pre RM Opening Time]]<WFTracker[[#This Row],[Old vs New Order Lead Time WF dead line]], "LATE BY ENG", "ON TIME BY ENG") -> ON TIME BY ENG | AC11: =IF(WFTracker[[#This Row],[Competion Date Content]] = FALSE, "C", "I") -> C | AD11: =IF(WFTracker[[#This Row],[Competion Date Content]]=TRUE,NETWORKDAYS.INTL(WFTracker[[#This Row],[RM]],TODAY(),1,Holidays!$D$4:$D$19), NETWORKDAYS.INTL(WFTracker[[#This Row],[RM]],WFTracker[[#This Row],[Completion Date]],1,Holidays!$D$4:$D$19)) -> 8 | AE11: =IF(WFTracker[[#This Row],[Impact Time Post RM]]>0, "IMPACTED", "NOT IMPACTED") -> IMPACTED | AH11: =IF(WFTracker[[#This Row],[Status]]="C", "Closed", IF(WFTracker[[#This Row],[Status]] = "x", "Cancelled", WFTracker[[#This Row],[Impact Time Post RM]])) -> Closed | AI11: =IF(WFTracker[[#This Row],[Impact Time Post RM]]<=0,"ON TIME","LATE") -> LATE | AJ11: NA | AK11: 18 | AL11: =IF(WFTracker[[#This Row],[Type]]="MAKE", WFTracker[[#This Row],[Due date]]+Filters!$J$111, WFTracker[[#This Row],[Due date]]+Filters!$J$135) -> 45711.073 | AM11: {=_xlfn.IFS(WFTracker[[#This Row],[Type]]="BUY", WFTracker[[#This Row],[Task Number]]/17, WFTracker[[#This Row],[Type]]="MAKE", WFTracker[[#This Row],[Task Number]]/18, WFTracker[[#This Row],[Type]]="CNG-BOM", WFTracker[[#This Row],[Task Number]]/11)} -> 1
A12: =IF(WFTracker[[#This Row],[Order Number]]="SWBD", "QED2", "PZ4") -> PZ4 | B12: 0051035283 | C12: 0000010&0000050 | D12: =WFTracker[[#This Row],[Order Number]] & "-" & WFTracker[[#This Row],[Item]] -> 0051035283-0000010&0000050 | E12: SWITCHGEAR UPGRADE | F12: 45709 | H12: LGS | I12: OAL | J12: WF1647369 | K12: Elec | L12: MAKE | M12: ANSI 49 | N12: 45835 | O12: =NETWORKDAYS.INTL(WFTracker[[#This Row],[Start date]],WFTracker[[#This Row],[RM]],1,Holidays!D87:D102) -> 5 | P12: 45705 | Q12: 45712 | R12: 45720 | S12: =ISBLANK(WFTracker[[#This Row],[Completion Date]]) -> FALSE | T12: =TEXT(WFTracker[[#This Row],[Start date]],"mmm-yyyy") -> Feb-2025 | U12: 5 | V12: =NETWORKDAYS.INTL(WFTracker[[#This Row],[Start date]],WFTracker[[#This Row],[Due date]],1,Holidays!D87:D102) -> 6 | W12: =IF(WFTracker[[#This Row],[Competion Date Content]]= TRUE, NETWORKDAYS.INTL( WFTracker[[#This Row],[Start date]],TODAY(),1,Holidays!$D$4:$D$19), NETWORKDAYS.INTL( WFTracker[[#This Row],[Start date]],WFTracker[[#This Row],[Completion Date]],1,Holidays!$D$4:$D$19)) -> 12 | X12: =WFTracker[[#This Row],[Active Time]]-WFTracker[[#This Row],[Completion Days Template]] -> 6 | Y12: =IF(WFTracker[[#This Row],[Overdue Time '[Expected-Completion']]]>0, "LATE","ON TIME") -> LATE | Z12: =IF(WFTracker[[#This Row],[Overdue Time '[Expected-Completion']]] >= 15, "SUPER LATE", Y12) -> LATE | AA12: =IF(WFTracker[[#This Row],[Pre RM Opening Time]]<WFTracker[[#This Row],[Old vs New Order Lead Time WF dead line]], "LATE BY ENG", "ON TIME BY ENG") -> ON TIME BY ENG | AC12: =IF(WFTracker[[#This Row],[Competion Date Content]] = FALSE, "C", "I") -> C | AD12: =IF(WFTracker[[#This Row],[Competion Date Content]]=TRUE,NETWORKDAYS.INTL(WFTracker[[#This Row],[RM]],TODAY(),1,Holidays!$D$4:$D$19), NETWORKDAYS.INTL(WFTracker[[#This Row],[RM]],WFTracker[[#This Row],[Completion Date]],1,Holidays!$D$4:$D$19)) -> 8 | AE12: =IF(WFTracker[[#This Row],[Impact Time Post RM]]>0, "IMPACTED", "NOT IMPACTED") -> IMPACTED | AH12: =IF(WFTracker[[#This Row],[Status]]="C", "Closed", IF(WFTracker[[#This Row],[Status]] = "x", "Cancelled", WFTracker[[#This Row],[Impact Time Post RM]])) -> Closed | AI12: =IF(WFTracker[[#This Row],[Impact Time Post RM]]<=0,"ON TIME","LATE") -> LATE | AJ12: NA | AK12: 18 | AL12: =IF(WFTracker[[#This Row],[Type]]="MAKE", WFTracker[[#This Row],[Due date]]+Filters!$J$111, WFTracker[[#This Row],[Due date]]+Filters!$J$135) -> 45715.073 | AM12: {=_xlfn.IFS(WFTracker[[#This Row],[Type]]="BUY", WFTracker[[#This Row],[Task Number]]/17, WFTracker[[#This Row],[Type]]="MAKE", WFTracker[[#This Row],[Task Number]]/18, WFTracker[[#This Row],[Type]]="CNG-BOM", WFTracker[[#This Row],[Task Number]]/11)} -> 1
A13: =IF(WFTracker[[#This Row],[Order Number]]="SWBD", "QED2", "PZ4") -> PZ4 | B13: 0050255139 | C13: 000780 | D13: =WFTracker[[#This Row],[Order Number]] & "-" & WFTracker[[#This Row],[Item]] -> 0050255139-000780 | E13: CHARLOTTE WATER-MT. HOLLY PS & STOWE - | F13: 45730 | H13: KYC | I13: VL | J13: WF1647350 | K13: Elec | L13: MAKE | M13: ANSI 49 | N13: 45960 | O13: =NETWORKDAYS.INTL(WFTracker[[#This Row],[Start date]],WFTracker[[#This Row],[RM]],1,Holidays!D468:D483) -> 20 | P13: 45705 | Q13: 45712 | R13: 45720 | S13: =ISBLANK(WFTracker[[#This Row],[Completion Date]]) -> FALSE | T13: =TEXT(WFTracker[[#This Row],[Start date]],"mmm-yyyy") -> Feb-2025 | U13: 5 | V13: =NETWORKDAYS.INTL(WFTracker[[#This Row],[Start date]],WFTracker[[#This Row],[Due date]],1,Holidays!D468:D483) -> 6 | W13: =IF(WFTracker[[#This Row],[Competion Date Content]]= TRUE, NETWORKDAYS.INTL( WFTracker[[#This Row],[Start date]],TODAY(),1,Holidays!$D$4:$D$19), NETWORKDAYS.INTL( WFTracker[[#This Row],[Start date]],WFTracker[[#This Row],[Completion Date]],1,Holidays!$D$4:$D$19)) -> 12 | X13: =WFTracker[[#This Row],[Active Time]]-WFTracker[[#This Row],[Completion Days Template]] -> 6 | Y13: =IF(WFTracker[[#This Row],[Overdue Time '[Expected-Completion']]]>0, "LATE","ON TIME") -> LATE | Z13: =IF(WFTracker[[#This Row],[Overdue Time '[Expected-Completion']]] >= 15, "SUPER LATE", Y13) -> LATE | AA13: =IF(WFTracker[[#This Row],[Pre RM Opening Time]]<WFTracker[[#This Row],[Old vs New Order Lead Time WF dead line]], "LATE BY ENG", "ON TIME BY ENG") -> ON TIME BY ENG | AC13: =IF(WFTracker[[#This Row],[Competion Date Content]] = FALSE, "C", "i") -> C | AD13: =IF(WFTracker[[#This Row],[Competion Date Content]]=TRUE,NETWORKDAYS.INTL(WFTracker[[#This Row],[RM]],TODAY(),1,Holidays!$D$4:$D$19), NETWORKDAYS.INTL(WFTracker[[#This Row],[RM]],WFTracker[[#This Row],[Completion Date]],1,Holidays!$D$4:$D$19)) -> -9 | AE13: =IF(WFTracker[[#This Row],[Impact Time Post RM]]>0, "IMPACTED", "NOT IMPACTED") -> NOT IMPACTED | AH13: =IF(WFTracker[[#This Row],[Status]]="C", "Closed", IF(WFTracker[[#This Row],[Status]] = "x", "Cancelled", WFTracker[[#This Row],[Impact Time Post RM]])) -> Closed | AI13: =IF(WFTracker[[#This Row],[Impact Time Post RM]]<=0,"ON TIME","LATE") -> ON TIME | AJ13: NA | AK13: 18 | AL13: =IF(WFTracker[[#This Row],[Type]]="MAKE", WFTracker[[#This Row],[Due date]]+Filters!$J$111, WFTracker[[#This Row],[Due date]]+Filters!$J$135) -> 45715.073 | AM13: {=_xlfn.IFS(WFTracker[[#This Row],[Type]]="BUY", WFTracker[[#This Row],[Task Number]]/17, WFTracker[[#This Row],[Type]]="MAKE", WFTracker[[#This Row],[Task Number]]/18, WFTracker[[#This Row],[Type]]="CNG-BOM", WFTracker[[#This Row],[Task Number]]/11)} -> 1
A14: =IF(WFTracker[[#This Row],[Order Number]]="SWBD", "QED2", "PZ4") -> PZ4 | B14: 0051035283 | C14: 0000010&0000050 | D14: =WFTracker[[#This Row],[Order Number]] & "-" & WFTracker[[#This Row],[Item]] -> 0051035283-0000010&0000050 | E14: SWITCHGEAR UPGRADE | F14: 45709 | H14: LGS | I14: OAL | J14: WF1648774 | K14: Elec | L14: MAKE | M14: ANSI 49 | N14: 45835 | O14: =NETWORKDAYS.INTL(WFTracker[[#This Row],[Start date]],WFTracker[[#This Row],[RM]],1,Holidays!D74:D89) -> 3 | P14: 45707 | Q14: 45714 | R14: 45715 | S14: =ISBLANK(WFTracker[[#This Row],[Completion Date]]) -> FALSE | T14: =TEXT(WFTracker[[#This Row],[Start date]],"mmm-yyyy") -> Feb-2025 | U14: 5 | V14: =NETWORKDAYS.INTL(WFTracker[[#This Row],[Start date]],WFTracker[[#This Row],[Due date]],1,Holidays!D74:D89) -> 6 | W14: =IF(WFTracker[[#This Row],[Competion Date Content]]= TRUE, NETWORKDAYS.INTL( WFTracker[[#This Row],[Start date]],TODAY(),1,Holidays!$D$4:$D$19), NETWORKDAYS.INTL( WFTracker[[#This Row],[Start date]],WFTracker[[#This Row],[Completion Date]],1,Holidays!$D$4:$D$19)) -> 7 | X14: =WFTracker[[#This Row],[Active Time]]-WFTracker[[#This Row],[Completion Days Template]] -> 1 | Y14: =IF(WFTracker[[#This Row],[Overdue Time '[Expected-Completion']]]>0, "LATE","ON TIME") -> LATE | Z14: =IF(WFTracker[[#This Row],[Overdue Time '[Expected-Completion']]] >= 15, "SUPER LATE", Y14) -> LATE | AA14: =IF(WFTracker[[#This Row],[Pre RM Opening Time]]<WFTracker[[#This Row],[Old vs New Order Lead Time WF dead line]], "LATE BY ENG", "ON TIME BY ENG") -> LATE BY ENG | AC14: =IF(WFTracker[[#This Row],[Competion Date Content]] = FALSE, "C", "I") -> C | AD14: =IF(WFTracker[[#This Row],[Competion Date Content]]=TRUE,NETWORKDAYS.INTL(WFTracker[[#This Row],[RM]],TODAY(),1,Holidays!$D$4:$D$19), NETWORKDAYS.INTL(WFTracker[[#This Row],[RM]],WFTracker[[#This Row],[Completion Date]],1,Holidays!$D$4:$D$19)) -> 5 | AE14: =IF(WFTracker[[#This Row],[Impact Time Post RM]]>0, "IMPACTED", "NOT IMPACTED") -> IMPACTED | AH14: =IF(WFTracker[[#This Row],[Status]]="C", "Closed", IF(WFTracker[[#This Row],[Status]] = "x", "Cancelled", WFTracker[[#This Row],[Impact Time Post RM]])) -> Closed | AI14: =IF(WFTracker[[#This Row],[Impact Time Post RM]]<=0,"ON TIME","LATE") -> LATE | AJ14: NA | AK14: 18 | AL14: =IF(WFTracker[[#This Row],[Type]]="MAKE", WFTracker[[#This Row],[Due date]]+Filters!$J$111, WFTracker[[#This Row],[Due date]]+Filters!$J$135) -> 45717.073 | AM14: {=_xlfn.IFS(WFTracker[[#This Row],[Type]]="BUY", WFTracker[[#This Row],[Task Number]]/17, WFTracker[[#This Row],[Type]]="MAKE", WFTracker[[#This Row],[Task Number]]/18, WFTracker[[#This Row],[Type]]="CNG-BOM", WFTracker[[#This Row],[Task Number]]/11)} -> 1
A15: =IF(WFTracker[[#This Row],[Order Number]]="SWBD", "QED2", "PZ4") -> PZ4 | B15: 0050206201 | C15: 000160 | D15: =WFTracker[[#This Row],[Order Number]] & "-" & WFTracker[[#This Row],[Item]] -> 0050206201-000160 | E15: AT&T GREENWOOD - GEAR ORDER | F15: 45769 | H15: JAM | I15: ADL | J15: WF1648985 | K15: Elec | L15: MAKE | M15: ANSI 49 | N15: 45868 | O15: =NETWORKDAYS.INTL(WFTracker[[#This Row],[Start date]],WFTracker[[#This Row],[RM]],1,Holidays!D614:D629) -> 45 | P15: 45707 | Q15: 45715 | R15: 45715 | S15: =ISBLANK(WFTracker[[#This Row],[Completion Date]]) -> FALSE | T15: =TEXT(WFTracker[[#This Row],[Start date]],"mmm-yyyy") -> Feb-2025 | U15: 5 | V15: =NETWORKDAYS.INTL(WFTracker[[#This Row],[Start date]],WFTracker[[#This Row],[Due date]],1,Holidays!D614:D629) -> 7 | W15: =IF(WFTracker[[#This Row],[Competion Date Content]]= TRUE, NETWORKDAYS.INTL( WFTracker[[#This Row],[Start date]],TODAY(),1,Holidays!$D$4:$D$19), NETWORKDAYS.INTL( WFTracker[[#This Row],[Start date]],WFTracker[[#This Row],[Completion Date]],1,Holidays!$D$4:$D$19)) -> 7 | X15: =WFTracker[[#This Row],[Active Time]]-WFTracker[[#This Row],[Completion Days Template]] -> 0 | Y15: =IF(WFTracker[[#This Row],[Overdue Time '[Expected-Completion']]]>0, "LATE","ON TIME") -> ON TIME | Z15: =IF(WFTracker[[#This Row],[Overdue Time '[Expected-Completion']]] >= 15, "SUPER LATE", Y15) -> ON TIME | AA15: =IF(WFTracker[[#This Row],[Pre RM Opening Time]]<WFTracker[[#This Row],[Old vs New Order Lead Time WF dead line]], "LATE BY ENG", "ON TIME BY ENG") -> ON TIME BY ENG | AC15: C | AD15: =IF(WFTracker[[#This Row],[Competion Date Content]]=TRUE,NETWORKDAYS.INTL(WFTracker[[#This Row],[RM]],TODAY(),1,Holidays!$D$4:$D$19), NETWORKDAYS.INTL(WFTracker[[#This Row],[RM]],WFTracker[[#This Row],[Completion Date]],1,Holidays!$D$4:$D$19)) -> -36 | AE15: =IF(WFTracker[[#This Row],[Impact Time Post RM]]>0, "IMPACTED", "NOT IMPACTED") -> NOT IMPACTED | AH15: =IF(WFTracker[[#This Row],[Status]]="C", "Closed", IF(WFTracker[[#This Row],[Status]] = "x", "Cancelled", WFTracker[[#This Row],[Impact Time Post RM]])) -> Closed | AI15: =IF(WFTracker[[#This Row],[Impact Time Post RM]]<=0,"ON TIME","LATE") -> ON TIME | AJ15: NA | AK15: 18 | AL15: =IF(WFTracker[[#This Row],[Type]]="MAKE", WFTracker[[#This Row],[Due date]]+Filters!$J$111, WFTracker[[#This Row],[Due date]]+Filters!$J$135) -> 45718.073 | AM15: {=_xlfn.IFS(WFTracker[[#This Row],[Type]]="BUY", WFTracker[[#This Row],[Task Number]]/17, WFTracker[[#This Row],[Type]]="MAKE", WFTracker[[#This Row],[Task Number]]/18, WFTracker[[#This Row],[Type]]="CNG-BOM", WFTracker[[#This Row],[Task Number]]/11)} -> 1
A16: =IF(WFTracker[[#This Row],[Order Number]]="SWBD", "QED2", "PZ4") -> PZ4 | B16: 0050255139 | C16: 000780 | D16: =WFTracker[[#This Row],[Order Number]] & "-" & WFTracker[[#This Row],[Item]] -> 0050255139-000780 | E16: CHARLOTTE WATER-MT. HOLLY PS & STOWE - | F16: 45730 | H16: KYC | I16: VL | J16: WF1650970 | K16: Mech | L16: MAKE | M16: ANSI 49 | N16: 45960 | O16: =NETWORKDAYS.INTL(WFTracker[[#This Row],[Start date]],WFTracker[[#This Row],[RM]],1,Holidays!D356:D371) -> 15 | P16: 45712 | Q16: 45719 | R16: 45727 | S16: =ISBLANK(WFTracker[[#This Row],[Completion Date]]) -> FALSE | T16: =TEXT(WFTracker[[#This Row],[Start date]],"mmm-yyyy") -> Feb-2025 | U16: 5 | V16: =NETWORKDAYS.INTL(WFTracker[[#This Row],[Start date]],WFTracker[[#This Row],[Due date]],1,Holidays!D356:D371) -> 6 | W16: =IF(WFTracker[[#This Row],[Competion Date Content]]= TRUE, NETWORKDAYS.INTL( WFTracker[[#This Row],[Start date]],TODAY(),1,Holidays!$D$4:$D$19), NETWORKDAYS.INTL( WFTracker[[#This Row],[Start date]],WFTracker[[#This Row],[Completion Date]],1,Holidays!$D$4:$D$19)) -> 12 | X16: =WFTracker[[#This Row],[Active Time]]-WFTracker[[#This Row],[Completion Days Template]] -> 6 | Y16: =IF(WFTracker[[#This Row],[Overdue Time '[Expected-Completion']]]>0, "LATE","ON TIME") -> LATE | Z16: =IF(WFTracker[[#This Row],[Overdue Time '[Expected-Completion']]] >= 15, "SUPER LATE", Y16) -> LATE | AA16: =IF(WFTracker[[#This Row],[Pre RM Opening Time]]<WFTracker[[#This Row],[Old vs New Order Lead Time WF dead line]], "LATE BY ENG", "ON TIME BY ENG") -> ON TIME BY ENG | AC16: =IF(WFTracker[[#This Row],[Competion Date Content]] = FALSE, "C", "i") -> C | AD16: =IF(WFTracker[[#This Row],[Competion Date Content]]=TRUE,NETWORKDAYS.INTL(WFTracker[[#This Row],[RM]],TODAY(),1,Holidays!$D$4:$D$19), NETWORKDAYS.INTL(WFTracker[[#This Row],[RM]],WFTracker[[#This Row],[Completion Date]],1,Holidays!$D$4:$D$19)) -> -4 | AE16: =IF(WFTracker[[#This Row],[Impact Time Post RM]]>0, "IMPACTED", "NOT IMPACTED") -> NOT IMPACTED | AH16: =IF(WFTracker[[#This Row],[Status]]="C", "Closed", IF(WFTracker[[#This Row],[Status]] = "x", "Cancelled", WFTracker[[#This Row],[Impact Time Post RM]])) -> Closed | AI16: =IF(WFTracker[[#This Row],[Impact Time Post RM]]<=0,"ON TIME","LATE") -> ON TIME | AJ16: NA | AK16: 18 | AL16: =IF(WFTracker[[#This Row],[Type]]="MAKE", WFTracker[[#This Row],[Due date]]+Filters!$J$111, WFTracker[[#This Row],[Due date]]+Filters!$J$135) -> 45722.073 | AM16: {=_xlfn.IFS(WFTracker[[#This Row],[Type]]="BUY", WFTracker[[#This Row],[Task Number]]/17, WFTracker[[#This Row],[Type]]="MAKE", WFTracker[[#This Row],[Task Number]]/18, WFTracker[[#This Row],[Type]]="CNG-BOM", WFTracker[[#This Row],[Task Number]]/11)} -> 1
A17: =IF(WFTracker[[#This Row],[Order Number]]="SWBD", "QED2", "PZ4") -> PZ4 | B17: 0050206201 | C17: 000180 | D17: =WFTracker[[#This Row],[Order Number]] & "-" & WFTracker[[#This Row],[Item]] -> 0050206201-000180 | E17: AT&T GREENWOOD - GEAR ORDER | F17: 45762 | H17: MGL | I17: KGF | J17: WF1650858 | K17: Elec | L17: MAKE | M17: ANSI 49 | N17: 45888 | O17: =NETWORKDAYS.INTL(WFTracker[[#This Row],[Start date]],WFTracker[[#This Row],[RM]],1,Holidays!D596:D611) -> 37 | P17: 45712 | Q17: 45719 | R17: 45715 | S17: =ISBLANK(WFTracker[[#This Row],[Completion Date]]) -> FALSE | T17: =TEXT(WFTracker[[#This Row],[Start date]],"mmm-yyyy") -> Feb-2025 | U17: 5 | V17: =NETWORKDAYS.INTL(WFTracker[[#This Row],[Start date]],WFTracker[[#This Row],[Due date]],1,Holidays!D596:D611) -> 6 | W17: =IF(WFTracker[[#This Row],[Competion Date Content]]= TRUE, NETWORKDAYS.INTL( WFTracker[[#This Row],[Start date]],TODAY(),1,Holidays!$D$4:$D$19), NETWORKDAYS.INTL( WFTracker[[#This Row],[Start date]],WFTracker[[#This Row],[Completion Date]],1,Holidays!$D$4:$D$19)) -> 4 | X17: =WFTracker[[#This Row],[Active Time]]-WFTracker[[#This Row],[Completion Days Template]] -> -2 | Y17: =IF(WFTracker[[#This Row],[Overdue Time '[Expected-Completion']]]>0, "LATE","ON TIME") -> ON TIME | Z17: =IF(WFTracker[[#This Row],[Overdue Time '[Expected-Completion']]] >= 15, "SUPER LATE", Y17) -> ON TIME | AA17: =IF(WFTracker[[#This Row],[Pre RM Opening Time]]<WFTracker[[#This Row],[Old vs New Order Lead Time WF dead line]], "LATE BY ENG", "ON TIME BY ENG") -> ON TIME BY ENG | AC17: =IF(WFTracker[[#This Row],[Competion Date Content]] = FALSE, "C", "I") -> C | AD17: =IF(WFTracker[[#This Row],[Competion Date Content]]=TRUE,NETWORKDAYS.INTL(WFTracker[[#This Row],[RM]],TODAY(),1,Holidays!$D$4:$D$19), NETWORKDAYS.INTL(WFTracker[[#This Row],[RM]],WFTracker[[#This Row],[Completion Date]],1,Holidays!$D$4:$D$19)) -> -33 | AE17: =IF(WFTracker[[#This Row],[Impact Time Post RM]]>0, "IMPACTED", "NOT IMPACTED") -> NOT IMPACTED | AH17: =IF(WFTracker[[#This Row],[Status]]="C", "Closed", IF(WFTracker[[#This Row],[Status]] = "x", "Cancelled", WFTracker[[#This Row],[Impact Time Post RM]])) -> Closed | AI17: =IF(WFTracker[[#This Row],[Impact Time Post RM]]<=0,"ON TIME","LATE") -> ON TIME | AJ17: NA | AK17: 18 | AL17: =IF(WFTracker[[#This Row],[Type]]="MAKE", WFTracker[[#This Row],[Due date]]+Filters!$J$111, WFTracker[[#This Row],[Due date]]+Filters!$J$135) -> 45722.073 | AM17: {=_xlfn.IFS(WFTracker[[#This Row],[Type]]="BUY", WFTracker[[#This Row],[Task Number]]/17, WFTracker[[#This Row],[Type]]="MAKE", WFTracker[[#This Row],[Task Number]]/18, WFTracker[[#This Row],[Type]]="CNG-BOM", WFTracker[[#This Row],[Task Number]]/11)} -> 1
